Workbook

Sheet Movimentação
A1: Entrada/Saída | B1: Data | C1: Data | D1: Movimentação | E1: Produto | F1: Instituição | G1: Quantidade | H1: Preço unitário | I1: Valor da Operação
A2: Debito | B2: 05/06/2026 | C2: 46178 | D2: RESGATE ANTECIPADO/ | E2: CDB - CDB526CSFDK - BANCO DO BRASIL S/A | F2: BANCO DO BRASIL S/A | G2: 8000 | H2: 0.01000064 | I2: 80.01
A3: Debito | B3: 02/06/2026 | C3: 46175 | D3: Direitos de Subscrição - Não Exercido | E3: AFHI12 - AF INVEST CRI FDO. INV. IMOB - RECEBÍVEIS IMOB. | F3: XP INVESTIMENTOS CCTVM S/A | G3: 0 | H3: - | I3: -
A4: Credito | B4: 01/06/2026 | C4: 46174 | D4: Cessão de Direitos | E4: AFHI12 - AF INVEST CRI FDO. INV. IMOB - RECEBÍVEIS IMOB. | F4: XP INVESTIMENTOS CCTVM S/A | G4: 23 | H4: - | I4: -
A5: Debito | B5: 01/06/2026 | C5: 46174 | D5: Cessão de Direitos - Solicitada | E5: AFHI12 - AF INVEST CRI FDO. INV. IMOB - RECEBÍVEIS IMOB. | F5: XP INVESTIMENTOS CCTVM S/A | G5: 23 | H5: - | I5: -
A6: Debito | B6: 01/06/2026 | C6: 46174 | D6: RESGATE ANTECIPADO/ | E6: CDB - CDB526CSFDK - BANCO DO BRASIL S/A | F6: BANCO DO BRASIL S/A | G6: 5000 | H6: 0.01000032 | I6: 50
A7: Credito | B7: 01/06/2026 | C7: 46174 | D7: APLICAÇÃO | E7: CDB - CDB6260FY9K | F7: BANCO DO BRASIL S/A | G7: 2404334 | H7: 0.01 | I7: 24043.34
A8: Credito | B8: 01/06/2026 | C8: 46174 | D8: Juros Sobre Capital Próprio | E8: ITUB3 - ITAU UNIBANCO HOLDING S.A | F8: XP INVESTIMENTOS CCTVM S/A | G8: 526 | H8: 0.018 | I8: 7.89
A9: Debito | B9: 01/06/2026 | C9: 46174 | D9: Direitos de Subscrição - Não Exercido | E9: PMLL12 - GENIAL MALLS FUNDO DE INVESTIMENTO IMOBILIARIO | F9: XP INVESTIMENTOS CCTVM S/A | G9: 0 | H9: - | I9: -
A10: Credito | B10: 29/05/2026 | C10: 46171 | D10: Direito de Subscrição | E10: HGRU12 - PATRIA RENDA URBANA - FUNDO DE INVESTIMENTO IMOBILIARIO - RE | F10: XP INVESTIMENTOS CCTVM S/A | G10: 64 | H10: - | I10: -
A11: Credito | B11: 29/05/2026 | C11: 46171 | D11: Cessão de Direitos | E11: PMLL12 - GENIAL MALLS FUNDO DE INVESTIMENTO IMOBILIARIO | F11: XP INVESTIMENTOS CCTVM S/A | G11: 93 | H11: - | I11: -
A12: Debito | B12: 29/05/2026 | C12: 46171 | D12: Cessão de Direitos - Solicitada | E12: PMLL12 - GENIAL MALLS FUNDO DE INVESTIMENTO IMOBILIARIO | F12: XP INVESTIMENTOS CCTVM S/A | G12: 93 | H12: - | I12: -
A13: Credito | B13: 28/05/2026 | C13: 46170 | D13: Atualização | E13: PETR4 - PETROLEO BRASILEIRO S/A PETROBRAS | F13: XP INVESTIMENTOS CCTVM S/A | G13: 600 | H13: - | I13: -
A14: Credito | B14: 27/05/2026 | C14: 46169 | D14: APLICAÇÃO | E14: CDB - CDB526CSFDK | F14: BANCO DO BRASIL S/A | G14: 2473459 | H14: 0.01 | I14: 24734.59
A15: Credito | B15: 27/05/2026 | C15: 46169 | D15: Dividendo | E15: LEVE3 - MAHLE-METAL LEVE S.A. | F15: XP INVESTIMENTOS CCTVM S/A | G15: 600 | H15: 0.253 | I15: 152.01
A16: Credito | B16: 27/05/2026 | C16: 46169 | D16: Juros Sobre Capital Próprio | E16: LEVE3 - MAHLE-METAL LEVE S.A. | F16: XP INVESTIMENTOS CCTVM S/A | G16: 300 | H16: 0.206 | I16: 52.57
A17: Credito | B17: 27/05/2026 | C17: 46169 | D17: Dividendo | E17: LEVE3 - MAHLE-METAL LEVE S.A. | F17: XP INVESTIMENTOS CCTVM S/A | G17: 600 | H17: 1.783 | I17: 1069.74
A18: Credito | B18: 27/05/2026 | C18: 46169 | D18: Dividendo | E18: TAEE11 - TRANSMISSORA ALIANCA DE ENERGIA ELETRICA S/A | F18: XP INVESTIMENTOS CCTVM S/A | G18: 700 | H18: 0.153 | I18: 107.44
A19: Credito | B19: 27/05/2026 | C19: 46169 | D19: Dividendo | E19: TAEE11 - TRANSMISSORA ALIANCA DE ENERGIA ELETRICA S/A | F19: XP INVESTIMENTOS CCTVM S/A | G19: 700 | H19: 0.755 | I19: 528.76
A20: Credito | B20: 25/05/2026 | C20: 46167 | D20: Atualização | E20: BBSE3 - BB SEGURIDADE PARTICIPACOES S.A. | F20: XP INVESTIMENTOS CCTVM S/A | G20: 500 | H20: - | I20: -
A21: Credito | B21: 22/05/2026 | C21: 46164 | D21: Rendimento | E21: AFHI11 - AF INVEST CRI FDO. INV. IMOB - RECEBÍVEIS IMOB. | F21: XP INVESTIMENTOS CCTVM S/A | G21: 132 | H21: 1.03 | I21: 135.96
A22: Credito | B22: 20/05/2026 | C22: 46162 | D22: Direito de Subscrição | E22: AFHI12 - AF INVEST CRI FDO. INV. IMOB - RECEBÍVEIS IMOB. | F22: XP INVESTIMENTOS CCTVM S/A | G22: 23 | H22: - | I22: -
A23: Credito | B23: 20/05/2026 | C23: 46162 | D23: Juros Sobre Capital Próprio | E23: EGIE3 - ENGIE BRASIL ENERGIA S.A. | F23: XP INVESTIMENTOS CCTVM S/A | G23: 420 | H23: 0.088 | I23: 31.25
A24: Credito | B24: 20/05/2026 | C24: 46162 | D24: Dividendo | E24: EGIE3 - ENGIE BRASIL ENERGIA S.A. | F24: XP INVESTIMENTOS CCTVM S/A | G24: 620 | H24: 0.488 | I24: 302.73
A25: Credito | B25: 20/05/2026 | C25: 46162 | D25: Juros Sobre Capital Próprio | E25: PETR4 - PETROLEO BRASILEIRO S/A PETROBRAS | F25: XP INVESTIMENTOS CCTVM S/A | G25: 600 | H25: 0.313 | I25: 154.99
A26: Credito | B26: 20/05/2026 | C26: 46162 | D26: Rendimento | E26: PETR4 - PETROLEO BRASILEIRO S/A PETROBRAS | F26: XP INVESTIMENTOS CCTVM S/A | G26: 600 | H26: 0.016 | I26: 7.67
A27: Credito | B27: 19/05/2026 | C27: 46161 | D27: Direito de Subscrição | E27: PMLL12 - GENIAL MALLS FUNDO DE INVESTIMENTO IMOBILIARIO | F27: XP INVESTIMENTOS CCTVM S/A | G27: 93 | H27: - | I27: -
A28: Credito | B28: 18/05/2026 | C28: 46160 | D28: Rendimento | E28: PCIP11 - FDO INV. IMOB. VBI CRI | F28: XP INVESTIMENTOS CCTVM S/A | G28: 147 | H28: 0.89 | I28: 130.83
A29: Credito | B29: 15/05/2026 | C29: 46157 | D29: Dividendo | E29: CXSE3 - CAIXA SEGURIDADE PARTICIPACOES S/A | F29: XP INVESTIMENTOS CCTVM S/A | G29: 1000 | H29: 0.33 | I29: 330
A30: Credito | B30: 15/05/2026 | C30: 46157 | D30: Rendimento | E30: HGLG11 - PÁTRIA LOG - FDO INV IMOB - RESPONSABILIDADE LTDA. | F30: XP INVESTIMENTOS CCTVM S/A | G30: 99 | H30: 1.1 | I30: 108.9
A31: Credito | B31: 15/05/2026 | C31: 46157 | D31: Rendimento | E31: HGRU11 - PATRIA RENDA URBANA - FUNDO DE INVESTIMENTO IMOBILIARIO - RE | F31: XP INVESTIMENTOS CCTVM S/A | G31: 129 | H31: 0.95 | I31: 122.55
A32: Credito | B32: 15/05/2026 | C32: 46157 | D32: Rendimento | E32: PMLL11 - GENIAL MALLS FUNDO DE INVESTIMENTO IMOBILIARIO | F32: XP INVESTIMENTOS CCTVM S/A | G32: 153 | H32: 1 | I32: 153
A33: Credito | B33: 08/05/2026 | C33: 46150 | D33: Rendimento | E33: LVBI11 - FII LVBI VBI | F33: XP INVESTIMENTOS CCTVM S/A | G33: 113 | H33: 0.75 | I33: 84.75
A34: Credito | B34: 08/05/2026 | C34: 46150 | D34: Dividendo | E34: MGLU3 - MAGAZINE LUIZA S.A. | F34: XP INVESTIMENTOS CCTVM S/A | G34: 115 | H34: 0.081 | I34: 9.34
A35: Credito | B35: 05/05/2026 | C35: 46147 | D35: Dividendo | E35: FLRY3 - FLEURY S.A. | F35: XP INVESTIMENTOS CCTVM S/A | G35: 830 | H35: 0.404 | I35: 335.03
A36: Credito | B36: 04/05/2026 | C36: 46146 | D36: Juros Sobre Capital Próprio | E36: ITUB3 - ITAU UNIBANCO HOLDING S.A | F36: XP INVESTIMENTOS CCTVM S/A | G36: 526 | H36: 0.018 | I36: 7.89
A37: Credito | B37: 23/04/2026 | C37: 46135 | D37: Rendimento | E37: AFHI11 - AF INVEST CRI FDO. INV. IMOB - RECEBÍVEIS IMOB. | F37: XP INVESTIMENTOS CCTVM S/A | G37: 132 | H37: 0.98 | I37: 129.36
A38: Credito | B38: 16/04/2026 | C38: 46128 | D38: Rendimento | E38: PCIP11 - FDO INV. IMOB. VBI CRI | F38: XP INVESTIMENTOS CCTVM S/A | G38: 147 | H38: 0.85 | I38: 124.95
A39: Credito | B39: 15/04/2026 | C39: 46127 | D39: Rendimento | E39: HGLG11 - PÁTRIA LOG - FDO INV IMOB - RESPONSABILIDADE LTDA. | F39: XP INVESTIMENTOS CCTVM S/A | G39: 99 | H39: 1.1 | I39: 108.9
... A45: Credito | B45: 25/03/2026 | C45: 46106 | D45: Leilão de Fração | E45: MGLU3 - MAGAZINE LUIZA S.A. | F45: XP INVESTIMENTOS CCTVM S/A | G45: 0.5 | H45: 9.147 | I45: 4.57
...

Sheet Sheet2
A1: Movimentação | B1: nº ocorrencias | C1: descrição | F1: 1 | G1: 2 | H1: 3 | I1: 4 | J1: 5 | K1: 6 | L1: 7 | M1: 8 | N1: 9
F2: Entrada/Saída | G2: Data | H2: Data | I2: Movimentação | J2: Produto | K2: Instituição | L2: Quantidade | M2: Preço unitário | N2: Valor da Operação
A3: Rendimento | B3: =COUNTIF(Movimentação!D:D,A3) -> 587 | C3: rendimentos de FIIs | D3: =MATCH(A3,Movimentação!D:D,0) -> 21 | F3: =INDEX(Movimentação!$A:$I,$D3,F$1) -> Credito | G3: =INDEX(Movimentação!$A:$I,$D3,G$1) -> 22/05/2026 | H3: =INDEX(Movimentação!$A:$I,$D3,H$1) -> 46164 | I3: =INDEX(Movimentação!$A:$I,$D3,I$1) -> Rendimento | J3: =INDEX(Movimentação!$A:$I,$D3,J$1) -> AFHI11 - AF INVEST CRI FDO. INV. IMOB - RECEBÍVEIS IMOB. | K3: =INDEX(Movimentação!$A:$I,$D3,K$1) -> XP INVESTIMENTOS CCTVM S/A | L3: =INDEX(Movimentação!$A:$I,$D3,L$1) -> 132 | M3: =INDEX(Movimentação!$A:$I,$D3,M$1) -> 1.03 | N3: =INDEX(Movimentação!$A:$I,$D3,N$1) -> 135.96
A4: Juros Sobre Capital Próprio | B4: =COUNTIF(Movimentação!D:D,A4) -> 302 | C4: jcp de empresas listadas na B3 | D4: =MATCH(A4,Movimentação!D:D,0) -> 8 | F4: =INDEX(Movimentação!$A:$I,$D4,F$1) -> Credito | G4: =INDEX(Movimentação!$A:$I,$D4,G$1) -> 01/06/2026 | H4: =INDEX(Movimentação!$A:$I,$D4,H$1) -> 46174 | I4: =INDEX(Movimentação!$A:$I,$D4,I$1) -> Juros Sobre Capital Próprio | J4: =INDEX(Movimentação!$A:$I,$D4,J$1) -> ITUB3 - ITAU UNIBANCO HOLDING S.A | K4: =INDEX(Movimentação!$A:$I,$D4,K$1) -> XP INVESTIMENTOS CCTVM S/A | L4: =INDEX(Movimentação!$A:$I,$D4,L$1) -> 526 | M4: =INDEX(Movimentação!$A:$I,$D4,M$1) -> 0.018 | N4: =INDEX(Movimentação!$A:$I,$D4,N$1) -> 7.89
A5: Dividendo | B5: =COUNTIF(Movimentação!D:D,A5) -> 207 | C5: Dividendo de empresas listadas na B3 | D5: =MATCH(A5,Movimentação!D:D,0) -> 15 | F5: =INDEX(Movimentação!$A:$I,$D5,F$1) -> Credito | G5: =INDEX(Movimentação!$A:$I,$D5,G$1) -> 27/05/2026 | H5: =INDEX(Movimentação!$A:$I,$D5,H$1) -> 46169 | I5: =INDEX(Movimentação!$A:$I,$D5,I$1) -> Dividendo | J5: =INDEX(Movimentação!$A:$I,$D5,J$1) -> LEVE3 - MAHLE-METAL LEVE S.A. | K5: =INDEX(Movimentação!$A:$I,$D5,K$1) -> XP INVESTIMENTOS CCTVM S/A | L5: =INDEX(Movimentação!$A:$I,$D5,L$1) -> 600 | M5: =INDEX(Movimentação!$A:$I,$D5,M$1) -> 0.253 | N5: =INDEX(Movimentação!$A:$I,$D5,N$1) -> 152.01
A6: Transferência - Liquidação | B6: =COUNTIF(Movimentação!D:D,A6) -> 181 | C6: venda de ativos listados na b3. Ignorar. Usar o arquivo de negociações | D6: =MATCH(A6,Movimentação!D:D,0) -> 71 | F6: =INDEX(Movimentação!$A:$I,$D6,F$1) -> Debito | G6: =INDEX(Movimentação!$A:$I,$D6,G$1) -> 25/02/2026 | H6: =INDEX(Movimentação!$A:$I,$D6,H$1) -> 46078 | I6: =INDEX(Movimentação!$A:$I,$D6,I$1) -> Transferência - Liquidação | J6: =INDEX(Movimentação!$A:$I,$D6,J$1) -> VALE3 - VALE S.A. | K6: =INDEX(Movimentação!$A:$I,$D6,K$1) -> XP INVESTIMENTOS CCTVM S/A | L6: =INDEX(Movimentação!$A:$I,$D6,L$1) -> 200 | M6: =INDEX(Movimentação!$A:$I,$D6,M$1) -> 87.99 | N6: =INDEX(Movimentação!$A:$I,$D6,N$1) -> 17598
A7: Transferência | B7: =COUNTIF(Movimentação!D:D,A7) -> 81 | C7: transferencia de ativos entre corretoras. Deve ser tratado em pares, entre transações que ocorrem com o mesmo ativo no mesmo dia | D7: =MATCH(A7,Movimentação!D:D,0) -> 304 | F7: =INDEX(Movimentação!$A:$I,$D7,F$1) -> Credito | G7: =INDEX(Movimentação!$A:$I,$D7,G$1) -> 14/02/2025 | H7: =INDEX(Movimentação!$A:$I,$D7,H$1) -> 45702 | I7: =INDEX(Movimentação!$A:$I,$D7,I$1) -> Transferência | J7: =INDEX(Movimentação!$A:$I,$D7,J$1) -> B3SA3 - B3 S.A. - BRASIL, BOLSA, BALCÃO | K7: =INDEX(Movimentação!$A:$I,$D7,K$1) -> XP INVESTIMENTOS CCTVM S/A | L7: =INDEX(Movimentação!$A:$I,$D7,L$1) -> 700 | M7: =INDEX(Movimentação!$A:$I,$D7,M$1) -> - | N7: =INDEX(Movimentação!$A:$I,$D7,N$1) -> -
A8: Juros Sobre Capital Próprio - Transferido | B8: =COUNTIF(Movimentação!D:D,A8) -> 44 | C8: transferencia de JCP entre corretoras. Deve ser tratado em pares, entre transações que ocorrem com o mesmo ativo no mesmo dia | D8: =MATCH(A8,Movimentação!D:D,0) -> 312 | F8: =INDEX(Movimentação!$A:$I,$D8,F$1) -> Credito | G8: =INDEX(Movimentação!$A:$I,$D8,G$1) -> 14/02/2025 | H8: =INDEX(Movimentação!$A:$I,$D8,H$1) -> 45702 | I8: =INDEX(Movimentação!$A:$I,$D8,I$1) -> Juros Sobre Capital Próprio - Transferido | J8: =INDEX(Movimentação!$A:$I,$D8,J$1) -> ETER3 - ETERNIT S.A. | K8: =INDEX(Movimentação!$A:$I,$D8,K$1) -> XP INVESTIMENTOS CCTVM S/A | L8: =INDEX(Movimentação!$A:$I,$D8,L$1) -> 500 | M8: =INDEX(Movimentação!$A:$I,$D8,M$1) -> 0.052 | N8: =INDEX(Movimentação!$A:$I,$D8,N$1) -> 22.11
A9: Atualização | B9: =COUNTIF(Movimentação!D:D,A9) -> 39 | C9: ignorar | D9: =MATCH(A9,Movimentação!D:D,0) -> 13 | F9: =INDEX(Movimentação!$A:$I,$D9,F$1) -> Credito | G9: =INDEX(Movimentação!$A:$I,$D9,G$1) -> 28/05/2026 | H9: =INDEX(Movimentação!$A:$I,$D9,H$1) -> 46170 | I9: =INDEX(Movimentação!$A:$I,$D9,I$1) -> Atualização | J9: =INDEX(Movimentação!$A:$I,$D9,J$1) -> PETR4 - PETROLEO BRASILEIRO S/A PETROBRAS | K9: =INDEX(Movimentação!$A:$I,$D9,K$1) -> XP INVESTIMENTOS CCTVM S/A | L9: =INDEX(Movimentação!$A:$I,$D9,L$1) -> 600 | M9: =INDEX(Movimentação!$A:$I,$D9,M$1) -> - | N9: =INDEX(Movimentação!$A:$I,$D9,N$1) -> -
A10: Direito de Subscrição | B10: =COUNTIF(Movimentação!D:D,A10) -> 35 | C10: ignorar | D10: =MATCH(A10,Movimentação!D:D,0) -> 10 | F10: =INDEX(Movimentação!$A:$I,$D10,F$1) -> Credito | G10: =INDEX(Movimentação!$A:$I,$D10,G$1) -> 29/05/2026 | H10: =INDEX(Movimentação!$A:$I,$D10,H$1) -> 46171 | I10: =INDEX(Movimentação!$A:$I,$D10,I$1) -> Direito de Subscrição | J10: =INDEX(Movimentação!$A:$I,$D10,J$1) -> HGRU12 - PATRIA RENDA URBANA - FUNDO DE INVESTIMENTO IMOBILIARIO - RE | K10: =INDEX(Movimentação!$A:$I,$D10,K$1) -> XP INVESTIMENTOS CCTVM S/A | L10: =INDEX(Movimentação!$A:$I,$D10,L$1) -> 64 | M10: =INDEX(Movimentação!$A:$I,$D10,M$1) -> - | N10: =INDEX(Movimentação!$A:$I,$D10,N$1) -> -
A11: Direitos de Subscrição - Não Exercido | B11: =COUNTIF(Movimentação!D:D,A11) -> 34 | C11: ignorar | D11: =MATCH(A11,Movimentação!D:D,0) -> 3 | F11: =INDEX(Movimentação!$A:$I,$D11,F$1) -> Debito | G11: =INDEX(Movimentação!$A:$I,$D11,G$1) -> 02/06/2026 | H11: =INDEX(Movimentação!$A:$I,$D11,H$1) -> 46175 | I11: =INDEX(Movimentação!$A:$I,$D11,I$1) -> Direitos de Subscrição - Não Exercido | J11: =INDEX(Movimentação!$A:$I,$D11,J$1) -> AFHI12 - AF INVEST CRI FDO. INV. IMOB - RECEBÍVEIS IMOB. | K11: =INDEX(Movimentação!$A:$I,$D11,K$1) -> XP INVESTIMENTOS CCTVM S/A | L11: =INDEX(Movimentação!$A:$I,$D11,L$1) -> 0 | M11: =INDEX(Movimentação!$A:$I,$D11,M$1) -> - | N11: =INDEX(Movimentação!$A:$I,$D11,N$1) -> -
A12: Cessão de Direitos | B12: =COUNTIF(Movimentação!D:D,A12) -> 20 | C12: ignorar | D12: =MATCH(A12,Movimentação!D:D,0) -> 4 | F12: =INDEX(Movimentação!$A:$I,$D12,F$1) -> Credito | G12: =INDEX(Movimentação!$A:$I,$D12,G$1) -> 01/06/2026 | H12: =INDEX(Movimentação!$A:$I,$D12,H$1) -> 46174 | I12: =INDEX(Movimentação!$A:$I,$D12,I$1) -> Cessão de Direitos | J12: =INDEX(Movimentação!$A:$I,$D12,J$1) -> AFHI12 - AF INVEST CRI FDO. INV. IMOB - RECEBÍVEIS IMOB. | K12: =INDEX(Movimentação!$A:$I,$D12,K$1) -> XP INVESTIMENTOS CCTVM S/A | L12: =INDEX(Movimentação!$A:$I,$D12,L$1) -> 23 | M12: =INDEX(Movimentação!$A:$I,$D12,M$1) -> - | N12: =INDEX(Movimentação!$A:$I,$D12,N$1) -> -
A13: Cessão de Direitos - Solicitada | B13: =COUNTIF(Movimentação!D:D,A13) -> 20 | C13: ignorar | D13: =MATCH(A13,Movimentação!D:D,0) -> 5 | F13: =INDEX(Movimentação!$A:$I,$D13,F$1) -> Debito | G13: =INDEX(Movimentação!$A:$I,$D13,G$1) -> 01/06/2026 | H13: =INDEX(Movimentação!$A:$I,$D13,H$1) -> 46174 | I13: =INDEX(Movimentação!$A:$I,$D13,I$1) -> Cessão de Direitos - Solicitada | J13: =INDEX(Movimentação!$A:$I,$D13,J$1) -> AFHI12 - AF INVEST CRI FDO. INV. IMOB - RECEBÍVEIS IMOB. | K13: =INDEX(Movimentação!$A:$I,$D13,K$1) -> XP INVESTIMENTOS CCTVM S/A | L13: =INDEX(Movimentação!$A:$I,$D13,L$1) -> 23 | M13: =INDEX(Movimentação!$A:$I,$D13,M$1) -> - | N13: =INDEX(Movimentação!$A:$I,$D13,N$1) -> -
A14: Recibo de Subscrição | B14: =COUNTIF(Movimentação!D:D,A14) -> 18 | C14: ignorar | D14: =MATCH(A14,Movimentação!D:D,0) -> 1240 | F14: =INDEX(Movimentação!$A:$I,$D14,F$1) -> Credito | G14: =INDEX(Movimentação!$A:$I,$D14,G$1) -> 17/08/2021 | H14: =INDEX(Movimentação!$A:$I,$D14,H$1) -> 44425 | I14: =INDEX(Movimentação!$A:$I,$D14,I$1) -> Recibo de Subscrição | J14: =INDEX(Movimentação!$A:$I,$D14,J$1) -> XPML13 - XP MALLS FDO INV IMOB FII | K14: =INDEX(Movimentação!$A:$I,$D14,K$1) -> MODAL DTVM LTDA | L14: =INDEX(Movimentação!$A:$I,$D14,L$1) -> 8 | M14: =INDEX(Movimentação!$A:$I,$D14,M$1) -> - | N14: =INDEX(Movimentação!$A:$I,$D14,N$1) -> -
... A34: Incorporação | B34: =COUNTIF(Movimentação!D:D,A34) -> 1 | C34: ignorar | D34: =MATCH(A34,Movimentação!D:D,0) -> 1190 | F34: =INDEX(Movimentação!$A:$I,$D34,F$1) -> Credito | G34: =INDEX(Movimentação!$A:$I,$D34,G$1) -> 05/10/2021 | H34: =INDEX(Movimentação!$A:$I,$D34,H$1) -> 44474 | I34: =INDEX(Movimentação!$A:$I,$D34,I$1) -> Incorporação | J34: =INDEX(Movimentação!$A:$I,$D34,J$1) -> XPBR31 - XP INC. | K34: =INDEX(Movimentação!$A:$I,$D34,K$1) -> MODAL DTVM LTDA | L34: =INDEX(Movimentação!$A:$I,$D34,L$1) -> 6.92 | M34: =INDEX(Movimentação!$A:$I,$D34,M$1) -> - | N34: =INDEX(Movimentação!$A:$I,$D34,N$1) -> -
